# 16일차 리뷰

### Class.forName(ClassPath)

- ClassPath위치에 주어진 클래스가 있는지 찾아보는 코드

```java
public class ExceptionHandlingExample {
	
	public static void main(String[] args) {
		try {
			Class.forName("java.lang.String");
			System.out.println("java.lang.String 클래스가 존재합니다.");
		} catch(ClassNotFoundException e) {
			e.printStackTrace();
		}
		System.out.println();
		
		try {
			Class.forName("java.lang.String2");
			System.out.println("java.lang.String2 클래스가 존재합니다.");
		} catch(ClassNotFoundException e) {
			e.printStackTrace();
		}
	}
}
```

첫 번째 try문에서 java.lang.String은 존재하는 클래스이기 때문에 error를 발생시키지 않음

두 번째 try문제서 java.lang.String2는 존재하지 않는 클래스이기 때문에 ClassNotFoundException 발생

## 예외

**일반 예외(Exception)**

- <span style="color:Red">컴파일러가 예외 처리 코드 여부를 검사하는 예외를 말한다.</span>

**실행 예외(Runtime Exception)**

- <span style="color:red">컴파일러가 예외 처리 코드 여부를 검사하지 않는 예외를 말한다.</span>

![](https://raw.githubusercontent.com/nahyeonung/KCC_Java/main/KCC%EC%A0%95%EB%B3%B4%ED%86%B5%EC%8B%A0%202%EA%B8%B0%20%EC%88%98%EC%97%85%20%EB%A6%AC%EB%B7%B0/img/Frame%201.png)

# 예외 처리 코드(try문, throws)

## try-catch-finally문

- 예외 발생 여부와 상관없이 finally 블록은 항상 실행된다.(try문에 return이 있어도 finally는 실행된다.)
- <span style="color:red">e.getMessage(), e.printStackTrace(), e.toString()을 사용하여 에러 메세지를 확인할 수 있다.</span>
- <span style="color:red">너무 상위에 있는 예외를 사용하면 어떤 예외가 발생했는지 정확하게 파악하지 못하기 때문에 에러 대응을 제대로 못할 수 있다. ⇒ 그런 의미에서 다중 catch문을 사용할 때 하위 예외를 먼저 catch 해줘야 함</span>
- 하나의 catch 블록에 동일하게 예외 처리를 하고 싶을 때 catch 블록에 예외 클래스 기호 |로 연결하면 된다. ⇒ 상속 관계의 예외들을 연결할 순 없음

**하위 예외를 먼저 처리해주는 예제**

```java
public class ExceptionHandlingExample {
	public static void main(String[] args) {
		String[] array = {"100", "1oo"};
		
		for(int i=0; i<=array.length; i++) {
			try {
				int value = Integer.parseInt(array[i]);
				System.out.println("array[" + i + "]:" + value);
			}catch(ArrayIndexOutOfBoundsException e){
				System.out.println("배열 인덱스가 초과됨: " + e.getMessage());
			}
			catch(Exception e){
				System.out.println("실행에 문제가 있습니다.");
			}
		}
	}
}
```

**기호”|”를 사용한 예제**

```java
public class ExceptionalHandlingExample {
	public static void main(String[] args) {
		String[] array = {"100","1oo",null,"200"};
		
		for(int i=0; i<array.length; i++) {
			try {
				int value = Integer.parseInt(array[i]);
				System.out.println("array[" + i + "]:" + value);
			} catch(ArrayIndexOutOfBoundsException e) {
				System.out.println("배열 인덱스가 초과됨: " + e.getMessage());
			} catch(NullPointerException | NumberFormatException e) {
				System.out.println("데이터에 문제가 있음: " + e.getMessage());
			}
		}
	}
}
```

## 리소스 자동 닫기(try-with-resource)

- 리소스란 데이터를 제공하는 객체이다.
- 리소스를 사용하기 위해 열기(open), 닫기(close)가 필요하다.
- 리소스는 예외가 발생해도 닫는 것이 안전하다. 그래서 finally문에 자주 삽입하기도 하고, 더 간단하게 사용하기 위해서 try-with-resource 블록을 사용해서 처리할 수 있다.

**try-with-resource ⇒ try 괄호에 리소스를 여는 코드를 작성하면 try 블록이 정상적으로 실행을 완로했거나 도중에 예외가 발생하면 자동으로 리소스의 close() 메소드가 호출된다.**

<span style="color:red">try-with-resource를 사용하기 위해선 조건이 하나 있는데, AutoCloseable 인터페이스의 close() 메소드를 재정의해야 하는 것이다.</span>

```java
public class MyResource implements AutoCloseable {
	private String name;
	
	public MyResource(String name) {
		this.name = name;
		System.out.println("[MyResource(" + name + ") 열기");
	}
	
	public String read1() {
		System.out.println("[MyResource(" + name + ") 읽기");
		return "100";
	}
	
	public String read2() {
		System.out.println("[MyResource(" + name + ") 읽기");
		return "abc";
	}
	
	@Override
	public void close() throws Exception{
		System.out.println("[MyResource(" + name + ") 닫기");
	}
}
public class TryWithResourceExample {
	public static void main(String[] args) {
		try(MyResource res = new MyResource("A")){
			String data = res.read1();
			int value = Integer.parseInt(data);
		} catch(Exception e) {
			System.out.println("예외 처리: " +  e.getMessage());
		}
		System.out.println();
		
		try (MyResource res = new MyResource("A")){
			String data = res.read2();
			//NumberFormatException 발생
			int value = Integer.parseInt(data);
		} catch(Exception e) {
			System.out.println("예외 처리: " + e.getMessage());
		}
		System.out.println();
		
		MyResource res1 = new MyResource("첫번째");
		MyResource res2 = new MyResource("두번째");
		try(res1; res2){
			String data1 = res1.read1();
			String data2 = res2.read1();
		} catch(Exception e) {
			System.out.println("예외 처리: " + e.getMessage());
		}
	}
}
```

## 예외 떠넘기기(throws)

- 발생한 예외를 던지는 의미는 가지며, 예외 발생 가능성이 있는 곳에 throws를 붙여주고 예외가 발생되도록 할지 안 할지 선택권을 가지고 있는 곳(메소드)에 try-catch를 사용한다.
- 예를 들어, 분모에 들어갈 수를 받아서 나눗셈을 계산하는 메소드가 있다. 해당 메소드에 어떤 자연수를 넣어도 정상적으로 코드가 작동하지만 0을 넣으면 에러가 난다. 이때, 0을 넣을지 자연수를 넣을지 결정하는 메소드를 호출하는 부분에 try-catch를 해주고 메소드안에는 throws를 해준다.

```java
public class SelectException {
	public static void main(String[] args) {
		try {
			doIt(0); //예외를 발생시킬지의 선택권을 가진 곳에 try문 처리
		}catch(ArithmeticException e) {
			System.out.println(e.getMessage());
		}
		System.out.println("try문 종료");
	}
	
	public static void doIt(int data) throws ArithmeticException{
		int a = 1000/data; //예외가 발생할 가능성이 있음
		System.out.println(a);
	}
}
```

- main 메소드에서도 throws 키워드 사용해도 된다. 이땐 JVM이 최종적으로 예외 처리를 하고 다른 코드들은 실행되지 않는다.

## 예외 발생 시키기(throw)

- 직접 예외를 발생시키려면 throw 키워드와 함께 예외 객체를 제공하면 된다.
- throw new XxxException() 형태이다.

**위의 내용들을 활용하여 EmpVO라는 DAO 클래스를 통해 인터페이스를 상속받은 Service에서 SQLException을 예외처리하는 코드를 만들어보자.**

```java
public class EmpVO {
	private String a;
	private String b;
	private String c;
	private double d;
}
public interface IEmpService {
	void insert(EmpVO vo);
}
public class EmpService implements IEmpService{
	@Override
	public void insert(EmpVO vo) {
		try {
			if(vo == null) {
				throw new SQLException("객체가 널입니다.");
			} //if 블록을 수정하지 않고 예외 처리를 해야 함.	
			else {
				throw new IOException("null을 제외한 다른 값도 들어올 수 없습니다.");
			}
		}catch(SQLException e) {
			throw new RuntimeException(e);
		}catch(IOException e) {
			throw new RuntimeException(e);
		}
		
	}
}
public class EmpMain {
	public static void main(String[] args) {
		EmpVO aa = new EmpVO();
		IEmpService empService = new EmpService();
		try {
			empService.insert(aa);	
		} catch(RuntimeException e) {
			e.printStackTrace();
		}
		System.out.println("메인 종료");
	}
}
```

*<span style="color:orange">인터페이스는 어떤 클래스가 상속 받을지 모르기 때문에 함부로 throws 처리를 하면 나중에 곤란해지는 상황이 발생할 수 있다. 그래서 throws를 해주지 않아도 되는 RuntimeException을 사용해서 처리를 해줘야 한다!!</span>*